I'm sorry, but an uncaught exception occurred.

While running game code:
  File "game/script.rpy", line 49, in script
    LG1 "You've created a new Ren'Py game."
Exception: Sayer 'LG1' is not defined.

-- Full Traceback ------------------------------------------------------------

Full traceback:
  File "game/script.rpy", line 49, in script
    LG1 "You've created a new Ren'Py game."
  File "/Applications/renpy-8.2.3-sdk/renpy/ast.py", line 2560, in execute
    Say.execute(self)
  File "/Applications/renpy-8.2.3-sdk/renpy/ast.py", line 575, in execute
    who = eval_who(self.who, self.who_fast)
  File "/Applications/renpy-8.2.3-sdk/renpy/ast.py", line 464, in eval_who
    raise Exception("Sayer '%s' is not defined." % who)
Exception: Sayer 'LG1' is not defined.

macOS-13.5-arm64-arm-64bit arm64
Ren'Py 8.2.3.24061702
HowdyU Sleep 1.0
Thu May  8 13:50:06 2025
